Workbook

Sheet Claims Data
A1: Claim ID | B1: Date of Claim | C1: Type of Claim | D1: Claim Incurred ($) | E1: Claim Status | F1: Gross claim amount (HINT: Gross claim amount = Claim incurred + deductible) | G1: Policy Limits ($) | H1: Deductible ($) | I1: Cause of Loss | J1: Location | K1: Insured Party | L1: Gross Tonnage | M1: Prior Claims History | N1: Inflation Index | O1: Gross inflation adjusted claim (HINT: Gross inflation adjusted claim = gross claim * inflation index) | P1: Net inflation adjusted claim (HINT: Net inflation adjusted claim = Gross inflation adjusted claim - deductible) | Q1: Capped net adjusted incurred claim (HINT: Capped net adjusted incurred claim = net inflation adjusted claim capped at policy limit) | R1: Attritional claim flag - (set equal to 1 if claim is less than 1m, otherwise 0) | S1: Year
A2: CLM-00001 | B2: 43664 | C2: Collision Liability | D2: 737423.28 | E2: Closed | F2: =SUM(D2,H2) -> 749769.2 | G2: 5000000 | H2: 12345.92 | I2: Human Error | J2: Indian Ocean | K2: Company 9 | L2: =IF(C2="Cargo Liability",RANDBETWEEN(10000,80000),IF(C2="Collision Liability",RANDBETWEEN(20000,100000),IF(C2="Environmental Pollution",RANDBETWEEN(50000,120000),IF(C2="Damage to Other Vessels",RANDBETWEEN(15000,90000),IF(C2="Injury to Third Parties",RANDBETWEEN(5000,60000)))))) -> 87138 | M2: 4 | N2: =IF(YEAR(B2)=2023, 1.03, IF(YEAR(B2)=2022, 1.0506, IF(YEAR(B2)=2021, 1.071612, IF(YEAR(B2)=2020, 1.10376036, IF(YEAR(B2)=2019, 1.1479107744, IF(YEAR(B2)=2018, 1.20530631312, 1)))))) -> 1.1479108 | O2: =PRODUCT(F2,N2) -> 860668.14 | P2: =(O2-H2) -> 848322.22 | Q2: =MIN(P2,G2) -> 848322.22 | R2: =IF(Q2<1000000,1,0) -> 1 | S2: =YEAR(B2) -> 2019
A3: CLM-00002 | B3: 43978 | C3: Cargo Liability | D3: 315189.74 | E3: Closed | F3: =SUM(D3,H3) -> 348906.5 | G3: 5000000 | H3: 33716.76 | I3: Technical Failure | J3: Atlantic Ocean | K3: Company 4 | L3: =IF(C3="Cargo Liability",RANDBETWEEN(10000,80000),IF(C3="Collision Liability",RANDBETWEEN(20000,100000),IF(C3="Environmental Pollution",RANDBETWEEN(50000,120000),IF(C3="Damage to Other Vessels",RANDBETWEEN(15000,90000),IF(C3="Injury to Third Parties",RANDBETWEEN(5000,60000)))))) -> 72833 | M3: 6 | N3: =IF(YEAR(B3)=2023, 1.03, IF(YEAR(B3)=2022, 1.0506, IF(YEAR(B3)=2021, 1.071612, IF(YEAR(B3)=2020, 1.10376036, IF(YEAR(B3)=2019, 1.1479107744, IF(YEAR(B3)=2018, 1.20530631312, 1)))))) -> 1.1037604 | O3: =PRODUCT(F3,N3) -> 385109.16 | P3: =(O3-H3) -> 351392.4 | Q3: =MIN(P3,G3) -> 351392.4 | R3: =IF(Q3<1000000,1,0) -> 1 | S3: =YEAR(B3) -> 2020
A4: CLM-00003 | B4: 43427 | C4: Damage to Other Vessels | D4: 678364.99 | E4: Closed | F4: =SUM(D4,H4) -> 712761.9 | G4: 5000000 | H4: 34396.91 | I4: Criminal Activity | J4: Mediterranean Sea | K4: Company 2 | L4: =IF(C4="Cargo Liability",RANDBETWEEN(10000,80000),IF(C4="Collision Liability",RANDBETWEEN(20000,100000),IF(C4="Environmental Pollution",RANDBETWEEN(50000,120000),IF(C4="Damage to Other Vessels",RANDBETWEEN(15000,90000),IF(C4="Injury to Third Parties",RANDBETWEEN(5000,60000)))))) -> 49924 | M4: 3 | N4: =IF(YEAR(B4)=2023, 1.03, IF(YEAR(B4)=2022, 1.0506, IF(YEAR(B4)=2021, 1.071612, IF(YEAR(B4)=2020, 1.10376036, IF(YEAR(B4)=2019, 1.1479107744, IF(YEAR(B4)=2018, 1.20530631312, 1)))))) -> 1.2053063 | O4: =PRODUCT(F4,N4) -> 859096.42 | P4: =(O4-H4) -> 824699.51 | Q4: =MIN(P4,G4) -> 824699.51 | R4: =IF(Q4<1000000,1,0) -> 1 | S4: =YEAR(B4) -> 2018
A5: CLM-00004 | B5: 44201 | C5: Environmental Pollution | D5: 203840.58 | E5: Open | F5: =SUM(D5,H5) -> 215544.46 | G5: 5000000 | H5: 11703.88 | I5: Natural Disaster | J5: Pacific Ocean | K5: Company 17 | L5: =IF(C5="Cargo Liability",RANDBETWEEN(10000,80000),IF(C5="Collision Liability",RANDBETWEEN(20000,100000),IF(C5="Environmental Pollution",RANDBETWEEN(50000,120000),IF(C5="Damage to Other Vessels",RANDBETWEEN(15000,90000),IF(C5="Injury to Third Parties",RANDBETWEEN(5000,60000)))))) -> 109716 | M5: 7 | N5: =IF(YEAR(B5)=2023, 1.03, IF(YEAR(B5)=2022, 1.0506, IF(YEAR(B5)=2021, 1.071612, IF(YEAR(B5)=2020, 1.10376036, IF(YEAR(B5)=2019, 1.1479107744, IF(YEAR(B5)=2018, 1.20530631312, 1)))))) -> 1.071612 | O5: =PRODUCT(F5,N5) -> 230980.03 | P5: =(O5-H5) -> 219276.15 | Q5: =MIN(P5,G5) -> 219276.15 | R5: =IF(Q5<1000000,1,0) -> 1 | S5: =YEAR(B5) -> 2021
A6: CLM-00005 | B6: 45091 | C6: Injury to Third Parties | D6: 98692.46 | E6: In Litigation | F6: =SUM(D6,H6) -> 146820.18 | G6: 1000000 | H6: 48127.72 | I6: Human Error | J6: Indian Ocean | K6: Company 12 | L6: =IF(C6="Cargo Liability",RANDBETWEEN(10000,80000),IF(C6="Collision Liability",RANDBETWEEN(20000,100000),IF(C6="Environmental Pollution",RANDBETWEEN(50000,120000),IF(C6="Damage to Other Vessels",RANDBETWEEN(15000,90000),IF(C6="Injury to Third Parties",RANDBETWEEN(5000,60000)))))) -> 29036 | M6: 8 | N6: =IF(YEAR(B6)=2023, 1.03, IF(YEAR(B6)=2022, 1.0506, IF(YEAR(B6)=2021, 1.071612, IF(YEAR(B6)=2020, 1.10376036, IF(YEAR(B6)=2019, 1.1479107744, IF(YEAR(B6)=2018, 1.20530631312, 1)))))) -> 1.03 | O6: =PRODUCT(F6,N6) -> 151224.79 | P6: =(O6-H6) -> 103097.07 | Q6: =MIN(P6,G6) -> 103097.07 | R6: =IF(Q6<1000000,1,0) -> 1 | S6: =YEAR(B6) -> 2023
A7: CLM-00006 | B7: 43584 | C7: Collision Liability | D7: 243918.65 | E7: Closed | F7: =SUM(D7,H7) -> 254504.19 | G7: 5000000 | H7: 10585.54 | I7: Technical Failure | J7: Atlantic Ocean | K7: Company 3 | L7: =IF(C7="Cargo Liability",RANDBETWEEN(10000,80000),IF(C7="Collision Liability",RANDBETWEEN(20000,100000),IF(C7="Environmental Pollution",RANDBETWEEN(50000,120000),IF(C7="Damage to Other Vessels",RANDBETWEEN(15000,90000),IF(C7="Injury to Third Parties",RANDBETWEEN(5000,60000)))))) -> 68522 | M7: 2 | N7: =IF(YEAR(B7)=2023, 1.03, IF(YEAR(B7)=2022, 1.0506, IF(YEAR(B7)=2021, 1.071612, IF(YEAR(B7)=2020, 1.10376036, IF(YEAR(B7)=2019, 1.1479107744, IF(YEAR(B7)=2018, 1.20530631312, 1)))))) -> 1.1479108 | O7: =PRODUCT(F7,N7) -> 292148.1 | P7: =(O7-H7) -> 281562.56 | Q7: =MIN(P7,G7) -> 281562.56 | R7: =IF(Q7<1000000,1,0) -> 1 | S7: =YEAR(B7) -> 2019
A8: CLM-00007 | B8: 44398 | C8: Environmental Pollution | D8: 765873.46 | E8: Closed | F8: =SUM(D8,H8) -> 783218.83 | G8: 5000000 | H8: 17345.37 | I8: Natural Disaster | J8: North Sea | K8: Company 11 | L8: =IF(C8="Cargo Liability",RANDBETWEEN(10000,80000),IF(C8="Collision Liability",RANDBETWEEN(20000,100000),IF(C8="Environmental Pollution",RANDBETWEEN(50000,120000),IF(C8="Damage to Other Vessels",RANDBETWEEN(15000,90000),IF(C8="Injury to Third Parties",RANDBETWEEN(5000,60000)))))) -> 58012 | M8: 1 | N8: =IF(YEAR(B8)=2023, 1.03, IF(YEAR(B8)=2022, 1.0506, IF(YEAR(B8)=2021, 1.071612, IF(YEAR(B8)=2020, 1.10376036, IF(YEAR(B8)=2019, 1.1479107744, IF(YEAR(B8)=2018, 1.20530631312, 1)))))) -> 1.071612 | O8: =PRODUCT(F8,N8) -> 839306.7 | P8: =(O8-H8) -> 821961.33 | Q8: =MIN(P8,G8) -> 821961.33 | R8: =IF(Q8<1000000,1,0) -> 1 | S8: =YEAR(B8) -> 2021
A9: CLM-00008 | B9: 44638 | C9: Damage to Other Vessels | D9: 913843.77 | E9: Closed | F9: =SUM(D9,H9) -> 939444.11 | G9: 5000000 | H9: 25600.34 | I9: Criminal Activity | J9: Atlantic Ocean | K9: Company 5 | L9: =IF(C9="Cargo Liability",RANDBETWEEN(10000,80000),IF(C9="Collision Liability",RANDBETWEEN(20000,100000),IF(C9="Environmental Pollution",RANDBETWEEN(50000,120000),IF(C9="Damage to Other Vessels",RANDBETWEEN(15000,90000),IF(C9="Injury to Third Parties",RANDBETWEEN(5000,60000)))))) -> 43455 | M9: 0 | N9: =IF(YEAR(B9)=2023, 1.03, IF(YEAR(B9)=2022, 1.0506, IF(YEAR(B9)=2021, 1.071612, IF(YEAR(B9)=2020, 1.10376036, IF(YEAR(B9)=2019, 1.1479107744, IF(YEAR(B9)=2018, 1.20530631312, 1)))))) -> 1.0506 | O9: =PRODUCT(F9,N9) -> 986979.98 | P9: =(O9-H9) -> 961379.64 | Q9: =MIN(P9,G9) -> 961379.64 | R9: =IF(Q9<1000000,1,0) -> 1 | S9: =YEAR(B9) -> 2022
A10: CLM-00009 | B10: 44150 | C10: Cargo Liability | D10: 754890.21 | E10: Closed | F10: =SUM(D10,H10) -> 793074.65 | G10: 5000000 | H10: 38184.44 | I10: Technical Failure | J10: Mediterranean Sea | K10: Company 8 | L10: =IF(C10="Cargo Liability",RANDBETWEEN(10000,80000),IF(C10="Collision Liability",RANDBETWEEN(20000,100000),IF(C10="Environmental Pollution",RANDBETWEEN(50000,120000),IF(C10="Damage to Other Vessels",RANDBETWEEN(15000,90000),IF(C10="Injury to Third Parties",RANDBETWEEN(5000,60000)))))) -> 76818 | M10: 6 | N10: =IF(YEAR(B10)=2023, 1.03, IF(YEAR(B10)=2022, 1.0506, IF(YEAR(B10)=2021, 1.071612, IF(YEAR(B10)=2020, 1.10376036, IF(YEAR(B10)=2019, 1.1479107744, IF(YEAR(B10)=2018, 1.20530631312, 1)))))) -> 1.1037604 | O10: =PRODUCT(F10,N10) -> 875364.36 | P10: =(O10-H10) -> 837179.92 | Q10: =MIN(P10,G10) -> 837179.92 | R10: =IF(Q10<1000000,1,0) -> 1 | S10: =YEAR(B10) -> 2020
A11: CLM-00010 | B11: 43258 | C11: Collision Liability | D11: 600293.27 | E11: Open | F11: =SUM(D11,H11) -> 601436.52 | G11: 5000000 | H11: 1143.25 | I11: Human Error | J11: Atlantic Ocean | K11: Company 10 | L11: =IF(C11="Cargo Liability",RANDBETWEEN(10000,80000),IF(C11="Collision Liability",RANDBETWEEN(20000,100000),IF(C11="Environmental Pollution",RANDBETWEEN(50000,120000),IF(C11="Damage to Other Vessels",RANDBETWEEN(15000,90000),IF(C11="Injury to Third Parties",RANDBETWEEN(5000,60000)))))) -> 87356 | M11: 5 | N11: =IF(YEAR(B11)=2023, 1.03, IF(YEAR(B11)=2022, 1.0506, IF(YEAR(B11)=2021, 1.071612, IF(YEAR(B11)=2020, 1.10376036, IF(YEAR(B11)=2019, 1.1479107744, IF(YEAR(B11)=2018, 1.20530631312, 1)))))) -> 1.2053063 | O11: =PRODUCT(F11,N11) -> 724915.23 | P11: =(O11-H11) -> 723771.98 | Q11: =MIN(P11,G11) -> 723771.98 | R11: =IF(Q11<1000000,1,0) -> 1 | S11: =YEAR(B11) -> 2018
A12: CLM-00011 | B12: 44251 | C12: Environmental Pollution | D12: 320726.12 | E12: Closed | F12: =SUM(D12,H12) -> 363045.09 | G12: 5000000 | H12: 42318.97 | I12: Technical Failure | J12: North Sea | K12: Company 7 | L12: =IF(C12="Cargo Liability",RANDBETWEEN(10000,80000),IF(C12="Collision Liability",RANDBETWEEN(20000,100000),IF(C12="Environmental Pollution",RANDBETWEEN(50000,120000),IF(C12="Damage to Other Vessels",RANDBETWEEN(15000,90000),IF(C12="Injury to Third Parties",RANDBETWEEN(5000,60000)))))) -> 62131 | M12: 7 | N12: =IF(YEAR(B12)=2023, 1.03, IF(YEAR(B12)=2022, 1.0506, IF(YEAR(B12)=2021, 1.071612, IF(YEAR(B12)=2020, 1.10376036, IF(YEAR(B12)=2019, 1.1479107744, IF(YEAR(B12)=2018, 1.20530631312, 1)))))) -> 1.071612 | O12: =PRODUCT(F12,N12) -> 389043.47 | P12: =(O12-H12) -> 346724.5 | Q12: =MIN(P12,G12) -> 346724.5 | R12: =IF(Q12<1000000,1,0) -> 1 | S12: =YEAR(B12) -> 2021
A13: CLM-00012 | B13: 44180 | C13: Cargo Liability | D13: 195238.55 | E13: Closed | F13: =SUM(D13,H13) -> 220873.24 | G13: 1000000 | H13: 25634.69 | I13: Criminal Activity | J13: Mediterranean Sea | K13: Company 6 | L13: =IF(C13="Cargo Liability",RANDBETWEEN(10000,80000),IF(C13="Collision Liability",RANDBETWEEN(20000,100000),IF(C13="Environmental Pollution",RANDBETWEEN(50000,120000),IF(C13="Damage to Other Vessels",RANDBETWEEN(15000,90000),IF(C13="Injury to Third Parties",RANDBETWEEN(5000,60000)))))) -> 11945 | M13: 8 | N13: =IF(YEAR(B13)=2023, 1.03, IF(YEAR(B13)=2022, 1.0506, IF(YEAR(B13)=2021, 1.071612, IF(YEAR(B13)=2020, 1.10376036, IF(YEAR(B13)=2019, 1.1479107744, IF(YEAR(B13)=2018, 1.20530631312, 1)))))) -> 1.1037604 | O13: =PRODUCT(F13,N13) -> 243791.13 | P13: =(O13-H13) -> 218156.44 | Q13: =MIN(P13,G13) -> 218156.44 | R13: =IF(Q13<1000000,1,0) -> 1 | S13: =YEAR(B13) -> 2020
... A101: CLM-00100 | B101: 44922 | C101: Environmental Pollution | D101: 5000000 | E101: In Litigation | F101: =SUM(D101,H101) -> 5018723.8 | G101: 10000000 | H101: 18723.79 | I101: Natural Disaster | J101: Atlantic Ocean | K101: Company 15 | L101: =IF(C101="Cargo Liability",RANDBETWEEN(10000,80000),IF(C101="Collision Liability",RANDBETWEEN(20000,100000),IF(C101="Environmental Pollution",RANDBETWEEN(50000,120000),IF(C101="Damage to Other Vessels",RANDBETWEEN(15000,90000),IF(C101="Injury to Third Parties",RANDBETWEEN(5000,60000)))))) -> 58087 | M101: 9 | N101: =IF(YEAR(B101)=2023, 1.03, IF(YEAR(B101)=2022, 1.0506, IF(YEAR(B101)=2021, 1.071612, IF(YEAR(B101)=2020, 1.10376036, IF(YEAR(B101)=2019, 1.1479107744, IF(YEAR(B101)=2018, 1.20530631312, 1)))))) -> 1.0506 | O101: =PRODUCT(F101,N101) -> 5272671.2 | P101: =(O101-H101) -> 5253947.4 | Q101: =MIN(P101,G101) -> 5253947.4 | R101: =IF(Q101<1000000,1,0) -> 0 | S101: =YEAR(B101) -> 2022

Sheet Exploratory Template
C2: Use pivot tables to generate tables and check for trends
K4: Loss location Summary
C5: Given Assumptions | K5: Net claims incurred by loss location
B6: 1 | C6: Commission is 0% | L6: 2018 | M6: 2019 | N6: 2020 | O6: 2021 | P6: 2022 | Q6: 2023
B7: 2 | C7: No adjustment is required for claims development patters | K7: Atlantic Ocean | L7: =SUMIFS('Claims Data'!$Q$2:$Q$101,'Claims Data'!$J$2:$J$101,$K7,'Claims Data'!$S$2:$S$101,L$6) -> 2142028.4 | M7: =SUMIFS('Claims Data'!$Q$2:$Q$101,'Claims Data'!$J$2:$J$101,$K7,'Claims Data'!$S$2:$S$101,M$6) -> 3078681.3 | N7: =SUMIFS('Claims Data'!$Q$2:$Q$101,'Claims Data'!$J$2:$J$101,$K7,'Claims Data'!$S$2:$S$101,N$6) -> 2384580.5 | O7: =SUMIFS('Claims Data'!$Q$2:$Q$101,'Claims Data'!$J$2:$J$101,$K7,'Claims Data'!$S$2:$S$101,O$6) -> 3164451.9 | P7: =SUMIFS('Claims Data'!$Q$2:$Q$101,'Claims Data'!$J$2:$J$101,$K7,'Claims Data'!$S$2:$S$101,P$6) -> 7283308.6 | Q7: =SUMIFS('Claims Data'!$Q$2:$Q$101,'Claims Data'!$J$2:$J$101,$K7,'Claims Data'!$S$2:$S$101,Q$6) -> 1459094.7
B8: 3 | C8: Individual policies run from 1/1 - 31/12 each year | K8: Indian Ocean | L8: =SUMIFS('Claims Data'!$Q$2:$Q$101,'Claims Data'!$J$2:$J$101,$K8,'Claims Data'!$S$2:$S$101,L$6) -> 345659.15 | M8: =SUMIFS('Claims Data'!$Q$2:$Q$101,'Claims Data'!$J$2:$J$101,$K8,'Claims Data'!$S$2:$S$101,M$6) -> 2703365.8 | N8: =SUMIFS('Claims Data'!$Q$2:$Q$101,'Claims Data'!$J$2:$J$101,$K8,'Claims Data'!$S$2:$S$101,N$6) -> 2791088.7 | O8: =SUMIFS('Claims Data'!$Q$2:$Q$101,'Claims Data'!$J$2:$J$101,$K8,'Claims Data'!$S$2:$S$101,O$6) -> 1255557.6 | P8: =SUMIFS('Claims Data'!$Q$2:$Q$101,'Claims Data'!$J$2:$J$101,$K8,'Claims Data'!$S$2:$S$101,P$6) -> 1673107.9 | Q8: =SUMIFS('Claims Data'!$Q$2:$Q$101,'Claims Data'!$J$2:$J$101,$K8,'Claims Data'!$S$2:$S$101,Q$6) -> 103097.07
K9: Mediterranean Sea | L9: =SUMIFS('Claims Data'!$Q$2:$Q$101,'Claims Data'!$J$2:$J$101,$K9,'Claims Data'!$S$2:$S$101,L$6) -> 2038650.1 | M9: =SUMIFS('Claims Data'!$Q$2:$Q$101,'Claims Data'!$J$2:$J$101,$K9,'Claims Data'!$S$2:$S$101,M$6) -> 1402178.8 | N9: =SUMIFS('Claims Data'!$Q$2:$Q$101,'Claims Data'!$J$2:$J$101,$K9,'Claims Data'!$S$2:$S$101,N$6) -> 3983656.4 | O9: =SUMIFS('Claims Data'!$Q$2:$Q$101,'Claims Data'!$J$2:$J$101,$K9,'Claims Data'!$S$2:$S$101,O$6) -> 852809.66 | P9: =SUMIFS('Claims Data'!$Q$2:$Q$101,'Claims Data'!$J$2:$J$101,$K9,'Claims Data'!$S$2:$S$101,P$6) -> 3625547.2 | Q9: =SUMIFS('Claims Data'!$Q$2:$Q$101,'Claims Data'!$J$2:$J$101,$K9,'Claims Data'!$S$2:$S$101,Q$6) -> 816921.86
K10: North Sea | L10: =SUMIFS('Claims Data'!$Q$2:$Q$101,'Claims Data'!$J$2:$J$101,$K10,'Claims Data'!$S$2:$S$101,L$6) -> 1901894 | M10: =SUMIFS('Claims Data'!$Q$2:$Q$101,'Claims Data'!$J$2:$J$101,$K10,'Claims Data'!$S$2:$S$101,M$6) -> 1623374.5 | N10: =SUMIFS('Claims Data'!$Q$2:$Q$101,'Claims Data'!$J$2:$J$101,$K10,'Claims Data'!$S$2:$S$101,N$6) -> 0 | O10: =SUMIFS('Claims Data'!$Q$2:$Q$101,'Claims Data'!$J$2:$J$101,$K10,'Claims Data'!$S$2:$S$101,O$6) -> 1785612.8 | P10: =SUMIFS('Claims Data'!$Q$2:$Q$101,'Claims Data'!$J$2:$J$101,$K10,'Claims Data'!$S$2:$S$101,P$6) -> 1703600.6 | Q10: =SUMIFS('Claims Data'!$Q$2:$Q$101,'Claims Data'!$J$2:$J$101,$K10,'Claims Data'!$S$2:$S$101,Q$6) -> 3629817.9
K11: Pacific Ocean | L11: =SUMIFS('Claims Data'!$Q$2:$Q$101,'Claims Data'!$J$2:$J$101,$K11,'Claims Data'!$S$2:$S$101,L$6) -> 0 | M11: =SUMIFS('Claims Data'!$Q$2:$Q$101,'Claims Data'!$J$2:$J$101,$K11,'Claims Data'!$S$2:$S$101,M$6) -> 1557588.5 | N11: =SUMIFS('Claims Data'!$Q$2:$Q$101,'Claims Data'!$J$2:$J$101,$K11,'Claims Data'!$S$2:$S$101,N$6) -> 2913916.5 | O11: =SUMIFS('Claims Data'!$Q$2:$Q$101,'Claims Data'!$J$2:$J$101,$K11,'Claims Data'!$S$2:$S$101,O$6) -> 4907895.5 | P11: =SUMIFS('Claims Data'!$Q$2:$Q$101,'Claims Data'!$J$2:$J$101,$K11,'Claims Data'!$S$2:$S$101,P$6) -> 720119.69 | Q11: =SUMIFS('Claims Data'!$Q$2:$Q$101,'Claims Data'!$J$2:$J$101,$K11,'Claims Data'!$S$2:$S$101,Q$6) -> 1436945.9
C12: Average Gross Claim Amount | K12: Total | L12: =SUM(L7:L11) -> 6428231.6 | M12: =SUM(M7:M11) -> 10365189 | N12: =SUM(N7:N11) -> 12073242 | O12: =SUM(O7:O11) -> 11966327 | P12: =SUM(P7:P11) -> 15005684 | Q12: =SUM(Q7:Q11) -> 7445877.4
C13: =AVERAGE('Claims Data'!F2:F101) -> 606718.31
C15: Average Claim Amount (Adjusted for Inflation)
C16: =AVERAGE('Claims Data'!O2:O101) -> 662235.24 | K16: Claim count by loss location
L17: 2018 | M17: 2019 | N17: 2020 | O17: 2021 | P17: 2022 | Q17: 2023
C18: Average Claim Amount by Year (Adjusted for Inflation) | K18: Atlantic Ocean | L18: =COUNTIFS('Claims Data'!$J$2:$J$101,$K18,'Claims Data'!$S$2:$S$101,L$17) -> 3 | M18: =COUNTIFS('Claims Data'!$J$2:$J$101,$K18,'Claims Data'!$S$2:$S$101,M$17) -> 5 | N18: =COUNTIFS('Claims Data'!$J$2:$J$101,$K18,'Claims Data'!$S$2:$S$101,N$17) -> 4 | O18: =COUNTIFS('Claims Data'!$J$2:$J$101,$K18,'Claims Data'!$S$2:$S$101,O$17) -> 5 | P18: =COUNTIFS('Claims Data'!$J$2:$J$101,$K18,'Claims Data'!$S$2:$S$101,P$17) -> 4 | Q18: =COUNTIFS('Claims Data'!$J$2:$J$101,$K18,'Claims Data'!$S$2:$S$101,Q$17) -> 2
C19: Year | D19: Average Adjusted Claim | E19: Claim Count | F19: Total Adjusted Claims | K19: Indian Ocean | L19: =COUNTIFS('Claims Data'!$J$2:$J$101,$K19,'Claims Data'!$S$2:$S$101,L$17) -> 1 | M19: =COUNTIFS('Claims Data'!$J$2:$J$101,$K19,'Claims Data'!$S$2:$S$101,M$17) -> 5 | N19: =COUNTIFS('Claims Data'!$J$2:$J$101,$K19,'Claims Data'!$S$2:$S$101,N$17) -> 4 | O19: =COUNTIFS('Claims Data'!$J$2:$J$101,$K19,'Claims Data'!$S$2:$S$101,O$17) -> 3 | P19: =COUNTIFS('Claims Data'!$J$2:$J$101,$K19,'Claims Data'!$S$2:$S$101,P$17) -> 4 | Q19: =COUNTIFS('Claims Data'!$J$2:$J$101,$K19,'Claims Data'!$S$2:$S$101,Q$17) -> 1
C20: 2018 | D20: =AVERAGEIFS('Claims Data'!$O$2:$O$101,'Claims Data'!$S$2:$S$101,C20) -> 669173.2 | E20: =COUNTIFS('Claims Data'!$S$2:$S$101,C20) -> 10 | F20: =SUMIFS('Claims Data'!$O$2:$O$101,'Claims Data'!$S$2:$S$101,C20) -> 6691732 | K20: Mediterranean Sea | L20: =COUNTIFS('Claims Data'!$J$2:$J$101,$K20,'Claims Data'!$S$2:$S$101,L$17) -> 3 | M20: =COUNTIFS('Claims Data'!$J$2:$J$101,$K20,'Claims Data'!$S$2:$S$101,M$17) -> 2 | N20: =COUNTIFS('Claims Data'!$J$2:$J$101,$K20,'Claims Data'!$S$2:$S$101,N$17) -> 6 | O20: =COUNTIFS('Claims Data'!$J$2:$J$101,$K20,'Claims Data'!$S$2:$S$101,O$17) -> 1 | P20: =COUNTIFS('Claims Data'!$J$2:$J$101,$K20,'Claims Data'!$S$2:$S$101,P$17) -> 5 | Q20: =COUNTIFS('Claims Data'!$J$2:$J$101,$K20,'Claims Data'!$S$2:$S$101,Q$17) -> 2
C21: 2019 | D21: =AVERAGEIFS('Claims Data'!$O$2:$O$101,'Claims Data'!$S$2:$S$101,C21) -> 639793 | E21: =COUNTIFS('Claims Data'!$S$2:$S$101,C21) -> 17 | F21: =SUMIFS('Claims Data'!$O$2:$O$101,'Claims Data'!$S$2:$S$101,C21) -> 10876481 | K21: North Sea | L21: =COUNTIFS('Claims Data'!$J$2:$J$101,$K21,'Claims Data'!$S$2:$S$101,L$17) -> 3 | M21: =COUNTIFS('Claims Data'!$J$2:$J$101,$K21,'Claims Data'!$S$2:$S$101,M$17) -> 3 | N21: =COUNTIFS('Claims Data'!$J$2:$J$101,$K21,'Claims Data'!$S$2:$S$101,N$17) -> 0 | O21: =COUNTIFS('Claims Data'!$J$2:$J$101,$K21,'Claims Data'!$S$2:$S$101,O$17) -> 3 | P21: =COUNTIFS('Claims Data'!$J$2:$J$101,$K21,'Claims Data'!$S$2:$S$101,P$17) -> 3 | Q21: =COUNTIFS('Claims Data'!$J$2:$J$101,$K21,'Claims Data'!$S$2:$S$101,Q$17) -> 8
C22: 2020 | D22: =AVERAGEIFS('Claims Data'!$O$2:$O$101,'Claims Data'!$S$2:$S$101,C22) -> 636678.23 | E22: =COUNTIFS('Claims Data'!$S$2:$S$101,C22) -> 20 | F22: =SUMIFS('Claims Data'!$O$2:$O$101,'Claims Data'!$S$2:$S$101,C22) -> 12733565 | K22: Pacific Ocean | L22: =COUNTIFS('Claims Data'!$J$2:$J$101,$K22,'Claims Data'!$S$2:$S$101,L$17) -> 0 | M22: =COUNTIFS('Claims Data'!$J$2:$J$101,$K22,'Claims Data'!$S$2:$S$101,M$17) -> 2 | N22: =COUNTIFS('Claims Data'!$J$2:$J$101,$K22,'Claims Data'!$S$2:$S$101,N$17) -> 6 | O22: =COUNTIFS('Claims Data'!$J$2:$J$101,$K22,'Claims Data'!$S$2:$S$101,O$17) -> 8 | P22: =COUNTIFS('Claims Data'!$J$2:$J$101,$K22,'Claims Data'!$S$2:$S$101,P$17) -> 1 | Q22: =COUNTIFS('Claims Data'!$J$2:$J$101,$K22,'Claims Data'!$S$2:$S$101,Q$17) -> 3
C23: 2021 | D23: =AVERAGEIFS('Claims Data'!$O$2:$O$101,'Claims Data'!$S$2:$S$101,C23) -> 626237.13 | E23: =COUNTIFS('Claims Data'!$S$2:$S$101,C23) -> 20 | F23: =SUMIFS('Claims Data'!$O$2:$O$101,'Claims Data'!$S$2:$S$101,C23) -> 12524743 | K23: Total | L23: =SUM(L18:L22) -> 10 | M23: =SUM(M18:M22) -> 17 | N23: =SUM(N18:N22) -> 20 | O23: =SUM(O18:O22) -> 20 | P23: =SUM(P18:P22) -> 17 | Q23: =SUM(Q18:Q22) -> 16
C24: 2022 | D24: =AVERAGEIFS('Claims Data'!$O$2:$O$101,'Claims Data'!$S$2:$S$101,C24) -> 911278.74 | E24: =COUNTIFS('Claims Data'!$S$2:$S$101,C24) -> 17 | F24: =SUMIFS('Claims Data'!$O$2:$O$101,'Claims Data'!$S$2:$S$101,C24) -> 15491739
C25: 2023 | D25: =AVERAGEIFS('Claims Data'!$O$2:$O$101,'Claims Data'!$S$2:$S$101,C25) -> 494079.09 | E25: =COUNTIFS('Claims Data'!$S$2:$S$101,C25) -> 16 | F25: =SUMIFS('Claims Data'!$O$2:$O$101,'Claims Data'!$S$2:$S$101,C25) -> 7905265.4
C26: Total | D26: =AVERAGE('Claims Data'!O2:O101) -> 662235.24 | E26: =SUM(E20:E25) -> 100 | F26: =SUM(F20:F25) -> 66223524
K27: Average claim cost by loss location (severity)
L28: 2018 | M28: 2019 | N28: 2020 | O28: 2021 | P28: 2022 | Q28: 2023
K29: Atlantic Ocean | L29: =IFERROR(AVERAGEIFS('Claims Data'!$Q$2:$Q$101,'Claims Data'!$J$2:$J$101,$K29,'Claims Data'!$S$2:$S$101,L$28),"-") -> 714009.45 | M29: =IFERROR(AVERAGEIFS('Claims Data'!$Q$2:$Q$101,'Claims Data'!$J$2:$J$101,$K29,'Claims Data'!$S$2:$S$101,M$28),"-") -> 615736.25 | N29: =IFERROR(AVERAGEIFS('Claims Data'!$Q$2:$Q$101,'Claims Data'!$J$2:$J$101,$K29,'Claims Data'!$S$2:$S$101,N$28),"-") -> 596145.14 | O29: =IFERROR(AVERAGEIFS('Claims Data'!$Q$2:$Q$101,'Claims Data'!$J$2:$J$101,$K29,'Claims Data'!$S$2:$S$101,O$28),"-") -> 632890.37 | P29: =IFERROR(AVERAGEIFS('Claims Data'!$Q$2:$Q$101,'Claims Data'!$J$2:$J$101,$K29,'Claims Data'!$S$2:$S$101,P$28),"-") -> 1820827.1 | Q29: =IFERROR(AVERAGEIFS('Claims Data'!$Q$2:$Q$101,'Claims Data'!$J$2:$J$101,$K29,'Claims Data'!$S$2:$S$101,Q$28),"-") -> 729547.33
C30: Claim Type Summary | K30: Indian Ocean | L30: =IFERROR(AVERAGEIFS('Claims Data'!$Q$2:$Q$101,'Claims Data'!$J$2:$J$101,$K30,'Claims Data'!$S$2:$S$101,L$28),"-") -> 345659.15 | M30: =IFERROR(AVERAGEIFS('Claims Data'!$Q$2:$Q$101,'Claims Data'!$J$2:$J$101,$K30,'Claims Data'!$S$2:$S$101,M$28),"-") -> 540673.17 | N30: =IFERROR(AVERAGEIFS('Claims Data'!$Q$2:$Q$101,'Claims Data'!$J$2:$J$101,$K30,'Claims Data'!$S$2:$S$101,N$28),"-") -> 697772.18 | O30: =IFERROR(AVERAGEIFS('Claims Data'!$Q$2:$Q$101,'Claims Data'!$J$2:$J$101,$K30,'Claims Data'!$S$2:$S$101,O$28),"-") -> 418519.19 | P30: =IFERROR(AVERAGEIFS('Claims Data'!$Q$2:$Q$101,'Claims Data'!$J$2:$J$101,$K30,'Claims Data'!$S$2:$S$101,P$28),"-") -> 418276.97 | Q30: =IFERROR(AVERAGEIFS('Claims Data'!$Q$2:$Q$101,'Claims Data'!$J$2:$J$101,$K30,'Claims Data'!$S$2:$S$101,Q$28),"-") -> 103097.07
C31: Net claims incurred by claim type | K31: Mediterranean Sea | L31: =IFERROR(AVERAGEIFS('Claims Data'!$Q$2:$Q$101,'Claims Data'!$J$2:$J$101,$K31,'Claims Data'!$S$2:$S$101,L$28),"-") -> 679550.03 | M31: =IFERROR(AVERAGEIFS('Claims Data'!$Q$2:$Q$101,'Claims Data'!$J$2:$J$101,$K31,'Claims Data'!$S$2:$S$101,M$28),"-") -> 701089.41 | N31: =IFERROR(AVERAGEIFS('Claims Data'!$Q$2:$Q$101,'Claims Data'!$J$2:$J$101,$K31,'Claims Data'!$S$2:$S$101,N$28),"-") -> 663942.74 | O31: =IFERROR(AVERAGEIFS('Claims Data'!$Q$2:$Q$101,'Claims Data'!$J$2:$J$101,$K31,'Claims Data'!$S$2:$S$101,O$28),"-") -> 852809.66 | P31: =IFERROR(AVERAGEIFS('Claims Data'!$Q$2:$Q$101,'Claims Data'!$J$2:$J$101,$K31,'Claims Data'!$S$2:$S$101,P$28),"-") -> 725109.45 | Q31: =IFERROR(AVERAGEIFS('Claims Data'!$Q$2:$Q$101,'Claims Data'!$J$2:$J$101,$K31,'Claims Data'!$S$2:$S$101,Q$28),"-") -> 408460.93
D32: 2018 | E32: 2019 | F32: 2020 | G32: 2021 | H32: 2022 | I32: 2023 | K32: North Sea | L32: =IFERROR(AVERAGEIFS('Claims Data'!$Q$2:$Q$101,'Claims Data'!$J$2:$J$101,$K32,'Claims Data'!$S$2:$S$101,L$28),"-") -> 633964.65 | M32: =IFERROR(AVERAGEIFS('Claims Data'!$Q$2:$Q$101,'Claims Data'!$J$2:$J$101,$K32,'Claims Data'!$S$2:$S$101,M$28),"-") -> 541124.82 | N32: =IFERROR(AVERAGEIFS('Claims Data'!$Q$2:$Q$101,'Claims Data'!$J$2:$J$101,$K32,'Claims Data'!$S$2:$S$101,N$28),"-") -> - | O32: =IFERROR(AVERAGEIFS('Claims Data'!$Q$2:$Q$101,'Claims Data'!$J$2:$J$101,$K32,'Claims Data'!$S$2:$S$101,O$28),"-") -> 595204.27 | P32: =IFERROR(AVERAGEIFS('Claims Data'!$Q$2:$Q$101,'Claims Data'!$J$2:$J$101,$K32,'Claims Data'!$S$2:$S$101,P$28),"-") -> 567866.88 | Q32: =IFERROR(AVERAGEIFS('Claims Data'!$Q$2:$Q$101,'Claims Data'!$J$2:$J$101,$K32,'Claims Data'!$S$2:$S$101,Q$28),"-") -> 453727.24
C33: Cargo Liability | D33: =SUMIFS('Claims Data'!$Q$2:$Q$101,'Claims Data'!$C$2:$C$101,$C33,'Claims Data'!$S$2:$S$101,D$32) -> 697368.02 | E33: =SUMIFS('Claims Data'!$Q$2:$Q$101,'Claims Data'!$C$2:$C$101,$C33,'Claims Data'!$S$2:$S$101,E$32) -> 662834.33 | F33: =SUMIFS('Claims Data'!$Q$2:$Q$101,'Claims Data'!$C$2:$C$101,$C33,'Claims Data'!$S$2:$S$101,F$32) -> 3570921.3 | G33: =SUMIFS('Claims Data'!$Q$2:$Q$101,'Claims Data'!$C$2:$C$101,$C33,'Claims Data'!$S$2:$S$101,G$32) -> 1781773.2 | H33: =SUMIFS('Claims Data'!$Q$2:$Q$101,'Claims Data'!$C$2:$C$101,$C33,'Claims Data'!$S$2:$S$101,H$32) -> 2937526.7 | I33: =SUMIFS('Claims Data'!$Q$2:$Q$101,'Claims Data'!$C$2:$C$101,$C33,'Claims Data'!$S$2:$S$101,I$32) -> 1570662.9 | K33: Pacific Ocean | L33: =IFERROR(AVERAGEIFS('Claims Data'!$Q$2:$Q$101,'Claims Data'!$J$2:$J$101,$K33,'Claims Data'!$S$2:$S$101,L$28),"-") -> - | M33: =IFERROR(AVERAGEIFS('Claims Data'!$Q$2:$Q$101,'Claims Data'!$J$2:$J$101,$K33,'Claims Data'!$S$2:$S$101,M$28),"-") -> 778794.26 | N33: =IFERROR(AVERAGEIFS('Claims Data'!$Q$2:$Q$101,'Claims Data'!$J$2:$J$101,$K33,'Claims Data'!$S$2:$S$101,N$28),"-") -> 485652.75 | O33: =IFERROR(AVERAGEIFS('Claims Data'!$Q$2:$Q$101,'Claims Data'!$J$2:$J$101,$K33,'Claims Data'!$S$2:$S$101,O$28),"-") -> 613486.93 | P33: =IFERROR(AVERAGEIFS('Claims Data'!$Q$2:$Q$101,'Claims Data'!$J$2:$J$101,$K33,'Claims Data'!$S$2:$S$101,P$28),"-") -> 720119.69 | Q33: =IFERROR(AVERAGEIFS('Claims Data'!$Q$2:$Q$101,'Claims Data'!$J$2:$J$101,$K33,'Claims Data'!$S$2:$S$101,Q$28),"-") -> 478981.96
C34: Collision Liability | D34: =SUMIFS('Claims Data'!$Q$2:$Q$101,'Claims Data'!$C$2:$C$101,$C34,'Claims Data'!$S$2:$S$101,D$32) -> 2405966.1 | E34: =SUMIFS('Claims Data'!$Q$2:$Q$101,'Claims Data'!$C$2:$C$101,$C34,'Claims Data'!$S$2:$S$101,E$32) -> 3253999.9 | F34: =SUMIFS('Claims Data'!$Q$2:$Q$101,'Claims Data'!$C$2:$C$101,$C34,'Claims Data'!$S$2:$S$101,F$32) -> 0 | G34: =SUMIFS('Claims Data'!$Q$2:$Q$101,'Claims Data'!$C$2:$C$101,$C34,'Claims Data'!$S$2:$S$101,G$32) -> 4027741.5 | H34: =SUMIFS('Claims Data'!$Q$2:$Q$101,'Claims Data'!$C$2:$C$101,$C34,'Claims Data'!$S$2:$S$101,H$32) -> 997566.68 | I34: =SUMIFS('Claims Data'!$Q$2:$Q$101,'Claims Data'!$C$2:$C$101,$C34,'Claims Data'!$S$2:$S$101,I$32) -> 1410599.6 | K34: Total | L34: =IFERROR(AVERAGE(L29:L33),"-") -> 593295.82 | M34: =IFERROR(AVERAGE(M29:M33),"-") -> 635483.58 | N34: =IFERROR(AVERAGE(N29:N33),"-") -> 610878.2 | O34: =IFERROR(AVERAGE(O29:O33),"-") -> 622582.08 | P34: =IFERROR(AVERAGE(P29:P33),"-") -> 850440.03 | Q34: =IFERROR(AVERAGE(Q29:Q33),"-") -> 434762.91
C35: Damage to Other Vessels | D35: =SUMIFS('Claims Data'!$Q$2:$Q$101,'Claims Data'!$C$2:$C$101,$C35,'Claims Data'!$S$2:$S$101,D$32) -> 1324699.5 | E35: =SUMIFS('Claims Data'!$Q$2:$Q$101,'Claims Data'!$C$2:$C$101,$C35,'Claims Data'!$S$2:$S$101,E$32) -> 2407881.4 | F35: =SUMIFS('Claims Data'!$Q$2:$Q$101,'Claims Data'!$C$2:$C$101,$C35,'Claims Data'!$S$2:$S$101,F$32) -> 3050494.7 | G35: =SUMIFS('Claims Data'!$Q$2:$Q$101,'Claims Data'!$C$2:$C$101,$C35,'Claims Data'!$S$2:$S$101,G$32) -> 2386006.6 | H35: =SUMIFS('Claims Data'!$Q$2:$Q$101,'Claims Data'!$C$2:$C$101,$C35,'Claims Data'!$S$2:$S$101,H$32) -> 2654253.8 | I35: =SUMIFS('Claims Data'!$Q$2:$Q$101,'Claims Data'!$C$2:$C$101,$C35,'Claims Data'!$S$2:$S$101,I$32) -> 834871.47
C36: Environmental Pollution | D36: =SUMIFS('Claims Data'!$Q$2:$Q$101,'Claims Data'!$C$2:$C$101,$C36,'Claims Data'!$S$2:$S$101,D$32) -> 0 | E36: =SUMIFS('Claims Data'!$Q$2:$Q$101,'Claims Data'!$C$2:$C$101,$C36,'Claims Data'!$S$2:$S$101,E$32) -> 3215152.3 | F36: =SUMIFS('Claims Data'!$Q$2:$Q$101,'Claims Data'!$C$2:$C$101,$C36,'Claims Data'!$S$2:$S$101,F$32) -> 3693140.9 | G36: =SUMIFS('Claims Data'!$Q$2:$Q$101,'Claims Data'!$C$2:$C$101,$C36,'Claims Data'!$S$2:$S$101,G$32) -> 3537852.8 | H36: =SUMIFS('Claims Data'!$Q$2:$Q$101,'Claims Data'!$C$2:$C$101,$C36,'Claims Data'!$S$2:$S$101,H$32) -> 8416336.8 | I36: =SUMIFS('Claims Data'!$Q$2:$Q$101,'Claims Data'!$C$2:$C$101,$C36,'Claims Data'!$S$2:$S$101,I$32) -> 0
C37: Injury to Third Parties | D37: =SUMIFS('Claims Data'!$Q$2:$Q$101,'Claims Data'!$C$2:$C$101,$C37,'Claims Data'!$S$2:$S$101,D$32) -> 2000197.9 | E37: =SUMIFS('Claims Data'!$Q$2:$Q$101,'Claims Data'!$C$2:$C$101,$C37,'Claims Data'!$S$2:$S$101,E$32) -> 825320.96 | F37: =SUMIFS('Claims Data'!$Q$2:$Q$101,'Claims Data'!$C$2:$C$101,$C37,'Claims Data'!$S$2:$S$101,F$32) -> 1758685.2 | G37: =SUMIFS('Claims Data'!$Q$2:$Q$101,'Claims Data'!$C$2:$C$101,$C37,'Claims Data'!$S$2:$S$101,G$32) -> 232953.22 | H37: =SUMIFS('Claims Data'!$Q$2:$Q$101,'Claims Data'!$C$2:$C$101,$C37,'Claims Data'!$S$2:$S$101,H$32) -> 0 | I37: =SUMIFS('Claims Data'!$Q$2:$Q$101,'Claims Data'!$C$2:$C$101,$C37,'Claims Data'!$S$2:$S$101,I$32) -> 3629743.5
C38: Total | D38: =SUM(D33:D37) -> 6428231.6 | E38: =SUM(E33:E37) -> 10365189 | F38: =SUM(F33:F37) -> 12073242 | G38: =SUM(G33:G37) -> 11966327 | H38: =SUM(H33:H37) -> 15005684 | I38: =SUM(I33:I37) -> 7445877.4
K39: Add some useful charts
K40: HINT: Net incurred claims by year and claim type
K41: HINT: Count of claims by year and claim type
C42: Claim count by claim type
D43: 2018 | E43: 2019 | F43: 2020 | G43: 2021 | H43: 2022 | I43: 2023
...

Sheet Pure Premium Work
G1: Claim frequency per gross tonnage
B2: Inflation Indices (Assumed for the Purpose of This Exercise): | G2: 1 | H2: Calculate the Loss Frequency using a pivot table, make sure to remove the large loss event. Claim frequency = Number of Claims/Gross Tonnage for all exposure.
D4: (1 + annual inflation) | E4: Inflation index | G4: Year | H4: Gross tonnage for all exposure | I4: No of claims | J4: Claim frequency per unit of gross tonnage
B5: 2018 | C5: 1.08 (8% inflation) | D5: 1.08 | E5: =E6*D6 -> 1.2053063 | G5: 2018 | H5: =C15 -> 45000000 | I5: =COUNTIFS('Claims Data'!$C$2:$C$101,"Environmental Pollution",'Claims Data'!$S$2:$S$101,G5,'Claims Data'!$R$2:$R$101,1) -> 0 | J5: =I5/H5 -> 0
B6: 2019 | C6: 1.05 (5% inflation) | D6: 1.05 | E6: =E7*D7 -> 1.1479108 | G6: =G5+1 -> 2019 | H6: =C16 -> 49000000 | I6: =COUNTIFS('Claims Data'!$C$2:$C$101,"Environmental Pollution",'Claims Data'!$S$2:$S$101,G6,'Claims Data'!$R$2:$R$101,1) -> 5 | J6: =I6/H6 -> 1.0204082e-07
B7: 2020 | C7: 1.04 (4% inflation) | D7: 1.04 | E7: =E8*D8 -> 1.1037604 | G7: =G6+1 -> 2020 | H7: =C17 -> 41750000 | I7: =COUNTIFS('Claims Data'!$C$2:$C$101,"Environmental Pollution",'Claims Data'!$S$2:$S$101,G7,'Claims Data'!$R$2:$R$101,1) -> 6 | J7: =I7/H7 -> 1.4371257e-07
B8: 2021 | C8: 1.03 (3% inflation) | D8: 1.03 | E8: =E9*D9 -> 1.071612 | G8: =G7+1 -> 2021 | H8: =C18 -> 41500000 | I8: =COUNTIFS('Claims Data'!$C$2:$C$101,"Environmental Pollution",'Claims Data'!$S$2:$S$101,G8,'Claims Data'!$R$2:$R$101,1) -> 6 | J8: =I8/H8 -> 1.4457831e-07
B9: 2022 | C9: 1.02 (2% inflation) | D9: 1.02 | E9: =E10*D10 -> 1.0506 | G9: =G8+1 -> 2022 | H9: =C19 -> 43590000 | I9: =COUNTIFS('Claims Data'!$C$2:$C$101,"Environmental Pollution",'Claims Data'!$S$2:$S$101,G9,'Claims Data'!$R$2:$R$101,1) -> 4 | J9: =I9/H9 -> 9.1764166e-08
B10: 2023 | C10: 1.02 (2% inflation) | D10: 1.02 | E10: =E11*D11 -> 1.03 | G10: =G9+1 -> 2023 | H10: =C20 -> 44750000 | I10: =COUNTIFS('Claims Data'!$C$2:$C$101,"Environmental Pollution",'Claims Data'!$S$2:$S$101,G10,'Claims Data'!$R$2:$R$101,1) -> 0 | J10: =I10/H10 -> 0
B11: 2024 | C11: 1.03 (3% expected over year) | D11: 1.03 | E11: 1 | G11: Total/Avg | I11: =SUM(I5:I10) -> 21 | J11: =AVERAGE(J5:J10) -> 8.0349312e-08
G12: Claim severity analysis (average cost per claim)
B13: Exposure information for the account provided by client | G13: 2 | H13: Calculate the Average cost per claim (Loss Severity) using a pivot table, make sure to remove the large loss event. Instructions: Create a pivot table with Year, Sum of Capped net inflation adjusted incurred claim and Count of Claim ID. Loss Severity= Sum of Capped net inflation adjusted incurred claim / Count of Claim ID for each year.
B14: Year | C14: Gross tonnage
B15: 2018 | C15: =45000000 -> 45000000
B16: =B15+1 -> 2019 | C16: 49000000
B17: =B16+1 -> 2020 | C17: 41750000 | G17: Year | H17: Sum of Capped Net Adj Claim | I17: No. of Claims | J17: Avg Cost (Severity)
B18: =B17+1 -> 2021 | C18: 41500000 | G18: 2018 | H18: =SUMIFS('Claims Data'!$Q$2:$Q$101,'Claims Data'!$C$2:$C$101,"Environmental Pollution",'Claims Data'!$S$2:$S$101,G18,'Claims Data'!$R$2:$R$101,1) -> 0 | I18: =I5 -> 0 | J18: =IFERROR(H18/I18,"-") -> -
B19: =B18+1 -> 2022 | C19: 43590000 | G19: 2019 | H19: =SUMIFS('Claims Data'!$Q$2:$Q$101,'Claims Data'!$C$2:$C$101,"Environmental Pollution",'Claims Data'!$S$2:$S$101,G19,'Claims Data'!$R$2:$R$101,1) -> 3215152.3 | I19: =I6 -> 5 | J19: =IFERROR(H19/I19,"-") -> 643030.47
B20: =B19+1 -> 2023 | C20: 44750000 | G20: 2020 | H20: =SUMIFS('Claims Data'!$Q$2:$Q$101,'Claims Data'!$C$2:$C$101,"Environmental Pollution",'Claims Data'!$S$2:$S$101,G20,'Claims Data'!$R$2:$R$101,1) -> 3693140.9 | I20: =I7 -> 6 | J20: =IFERROR(H20/I20,"-") -> 615523.49
G21: 2021 | H21: =SUMIFS('Claims Data'!$Q$2:$Q$101,'Claims Data'!$C$2:$C$101,"Environmental Pollution",'Claims Data'!$S$2:$S$101,G21,'Claims Data'!$R$2:$R$101,1) -> 3537852.8 | I21: =I8 -> 6 | J21: =IFERROR(H21/I21,"-") -> 589642.14
B22: 2024 expected gross tonnage provided by client | C22: 40000000 | G22: 2022 | H22: =SUMIFS('Claims Data'!$Q$2:$Q$101,'Claims Data'!$C$2:$C$101,"Environmental Pollution",'Claims Data'!$S$2:$S$101,G22,'Claims Data'!$R$2:$R$101,1) -> 3162389.4 | I22: =I9 -> 4 | J22: =IFERROR(H22/I22,"-") -> 790597.35
G23: 2023 | H23: =SUMIFS('Claims Data'!$Q$2:$Q$101,'Claims Data'!$C$2:$C$101,"Environmental Pollution",'Claims Data'!$S$2:$S$101,G23,'Claims Data'!$R$2:$R$101,1) -> 0 | I23: =I10 -> 0 | J23: =IFERROR(H23/I23,"-") -> -
C24: Given Assumptions | G24: Total/Avg | H24: =SUM(H18:H23) -> 13608535 | I24: =SUM(I18:I23) -> 21 | J24: =H24/I24 -> 648025.5
B25: 1 | C25: Commission is 0%
B26: 2 | C26: No adjustment is required for claims development patters
B27: 3 | C27: Deductibles in the upcoming policy period will be the same as deductible in prior policy periods. | G27: Loss cost calculation
B28: 4 | C28: Individual policies run from 1/1 - 31/12 each year | G28: 3 | H28: Complete the table below using the values derived in steps 1 and 2. HINT: Expected loss is the product of claim frequency and average claim severity.
B29: 5 | C29: Assume a large loss is any loss >$1m incurred
B30: 6 | C30: Assume the large loss event is a 1-in-20 year event. | G30: Loss cost | H30: Average cost per claim (Loss Severity) | I30: Claim frequency per unit of gross tonnage | J30: Expected loss per unit of gross tonnage
B31: 7 | C31: Assume expenses are 30% of the loss cost. | G31: 2018 | H31: =J18 -> - | I31: =J5 -> 0 | J31: =IFERROR(H31*I31,0) -> 0
B32: 8 | C32: Assume a 10% profit requirement on this account in calculating the premium | G32: 2019 | H32: =J19 -> 643030.47 | I32: =J6 -> 1.0204082e-07 | J32: =IFERROR(H32*I32,0) -> 0.065615354
G33: 2020 | H33: =J20 -> 615523.49 | I33: =J7 -> 1.4371257e-07 | J33: =IFERROR(H33*I33,0) -> 0.088458465
G34: 2021 | H34: =J21 -> 589642.14 | I34: =J8 -> 1.4457831e-07 | J34: =IFERROR(H34*I34,0) -> 0.085249466
G35: 2022 | H35: =J22 -> 790597.35 | I35: =J9 -> 9.1764166e-08 | J35: =IFERROR(H35*I35,0) -> 0.072548506
G36: 2023 | H36: =J23 -> - | I36: =J10 -> 0 | J36: =IFERROR(H36*I36,0) -> 0
A37: 5 | B37: Identify the Large Loss Event adjusted for inflation.
B38: Large Loss Event | G38: 4 | H38: Calculate the following using the values derived in step 3.
B39: =SUMIFS('Claims Data'!Q2:Q101,'Claims Data'!R2:R101,0,'Claims Data'!C2:C101,"Environmental Pollution") -> 5253947.4
A41: 6 | B41: Derive an appropriate Return Period. (Consider the information provided in the "Given Assumptions"). | G41: Average frequency per unit exposure | H41: =J11 -> 8.0349312e-08
B42: Return Period | G42: Average severity per claim | H42: =J24 -> 648025.5
...

Sheet Report
